<?xml version="1.0"?>
<robot xmlns:xacro="http://www.ros.org/wiki/xacro"
       name="scene" >


  <link name="world" />

  <joint name="world_temp_joint" type="revolute">
        <origin xyz="0 0 0" rpy="0 0 0"/>
        <parent link="world"/>
        <child link="temp"/>
        <limit effort="30" velocity="1.0" lower="-2.2" upper="0.7" />
    </joint>

  <link name="temp" />

  <joint name="world_temp_fixed_joint" type="fixed">
        <origin xyz="0 0 0" rpy="0 0 0"/>
        <parent link="world"/>
        <child link="temp_fixed"/>
    </joint>

  <link name="temp_fixed" />


</robot>
