<?xml version="1.0"?>
<robot name="kol_case_6DoF" xmlns:xacro="http://www.ros.org/wiki/xacro">


<xacro:macro name="kol_case_6DoF" params="name base_link">


    <property name="pos_lim" value="2"/>
    <property name="rot_lim" value="3.14"/>

    <!-- ===============  x link  =================-->

    <link name="${name}_x_link"/>

    <joint name="${name}_x_joint" type="prismatic">
        <origin xyz="0 0 0" rpy="0 0 0"/>
        <parent link="${base_link}"/>
        <child link="${name}_x_link"/>

        <axis xyz="1 0 0"/>
        <limit lower="${-pos_lim}" upper="${pos_lim}" effort="200" velocity="10"/>
    </joint>

    <!-- ===============  y link  =================-->

    <link name="${name}_y_link"/>

    <joint name="${name}_y_joint" type="prismatic">
        <origin xyz="0 0 0" rpy="0 0 0"/>
        <parent link="${name}_x_link"/>
        <child link="${name}_y_link"/>

        <axis xyz="0 1 0"/>
        <limit lower="${-pos_lim}" upper="${pos_lim}" effort="200" velocity="10"/>
    </joint>

    <!-- ===============  z link  =================-->

    <link name="${name}_z_link"/>

    <joint name="${name}_z_joint" type="prismatic">
        <origin xyz="0 0 0" rpy="0 0 0"/>
        <parent link="${name}_y_link"/>
        <child link="${name}_z_link"/>

        <axis xyz="0 0 1"/>
        <limit lower="${-pos_lim}" upper="${pos_lim}" effort="200" velocity="10"/>
    </joint>


    <!-- ===============  r link  =================-->

    <link name="${name}_roll_link"/>

    <joint name="${name}_roll_joint" type="revolute">
        <origin xyz="0 0 0" rpy="0 0 0"/>
        <parent link="${name}_z_link"/>
        <child link="${name}_roll_link"/>

        <axis xyz="1 0 0"/>
        <limit lower="${-rot_lim}" upper="${rot_lim}" effort="200" velocity="10"/>
    </joint>


    <!-- ===============  p link  =================-->

    <link name="${name}_pitch_link"/>

    <joint name="${name}_pitch_joint" type="revolute">
        <origin xyz="0 0 0" rpy="0 0 0"/>
        <parent link="${name}_roll_link"/>
        <child link="${name}_pitch_link"/>

        <axis xyz="0 1 0"/>
        <limit lower="${-rot_lim}" upper="${rot_lim}" effort="200" velocity="10"/>
    </joint>


    <!-- ===============  y link  =================-->

    <link name="${name}_yaw_link"/>

    <joint name="${name}_yaw_joint" type="revolute">
        <origin xyz="0 0 0" rpy="0 0 0"/>
        <parent link="${name}_pitch_link"/>
        <child link="${name}_yaw_link"/>

        <axis xyz="0 0 1"/>
        <limit lower="${-rot_lim}" upper="${rot_lim}" effort="200" velocity="10"/>
    </joint>


    <!-- ===============  kol_casing  =================-->
    <link name="${name}_kol_case_link">
        <visual>
            <origin xyz="-0.035 0.03 0" rpy="1.57 0 0" />
            <geometry>
                <mesh scale="0.001 0.001 0.001" filename="package://main_program/meshes/kol_casing.stl"/>
            </geometry>
            <material name="Blue">
               <color rgba="0 0 1 1.0"/>
             </material>
        </visual>
    </link>

    <joint name="${name}KolCaseLink_parent_joint" type="fixed">
        <origin xyz="0 0 0" rpy="0 0 0"/>
        <parent link="${name}_yaw_link"/>
        <child link="${name}_kol_case_link"/>
    </joint>


</xacro:macro>

</robot>
